  ███╗   ███╗██╗   ██╗███████╗██╗ ██████╗███████╗██████╗  ██████╗ ███████╗ ██████╗██╗  ██╗███╗   ███╗ ██████╗
  ████╗ ████║██║   ██║██╔════╝██║██╔════╝██╔════╝██╔══██╗██╔═══██╗██╔════╝██╔════╝██║  ██║████╗ ████║██╔════╝
  ██╔████╔██║██║   ██║███████╗██║██║     █████╗  ██████╔╝██║   ██║███████╗██║     ███████║██╔████╔██║██║     
  ██║╚██╔╝██║██║   ██║╚════██║██║██║     ██╔══╝  ██╔══██╗██║   ██║╚════██║██║     ██╔══██║██║╚██╔╝██║██║     
  ██║ ╚═╝ ██║╚██████╔╝███████║██║╚██████╗██║     ██║  ██║╚██████╔╝███████║╚██████╗██║  ██║██║ ╚═╝ ██║╚██████╗
  ╚═╝     ╚═╝ ╚═════╝ ╚══════╝╚═╝ ╚═════╝╚═╝     ╚═╝  ╚═╝ ╚═════╝ ╚══════╝ ╚═════╝╚═╝  ╚═╝╚═╝     ╚═╝ ╚═════╝
Current date and time: Sa 5. Apr 18:10:45 CEST 2025
Current folder: /

Traceback (most recent call last):
  File "/home/a163/anaconda3/envs/musikfrosch/lib/python3.11/site-packages/urllib3/connection.py", line 174, in _new_conn
    conn = connection.create_connection(
           ^^^^^^^^^^^^^^^^^^^^^^^^^^^^^
  File "/home/a163/anaconda3/envs/musikfrosch/lib/python3.11/site-packages/urllib3/util/connection.py", line 72, in create_connection
    for res in socket.getaddrinfo(host, port, family, socket.SOCK_STREAM):
               ^^^^^^^^^^^^^^^^^^^^^^^^^^^^^^^^^^^^^^^^^^^^^^^^^^^^^^^^^^
  File "/home/a163/anaconda3/envs/musikfrosch/lib/python3.11/socket.py", line 962, in getaddrinfo
    for res in _socket.getaddrinfo(host, port, family, type, proto, flags):
               ^^^^^^^^^^^^^^^^^^^^^^^^^^^^^^^^^^^^^^^^^^^^^^^^^^^^^^^^^^^
socket.gaierror: [Errno -3] Temporary failure in name resolution

During handling of the above exception, another exception occurred:

Traceback (most recent call last):
  File "/home/a163/anaconda3/envs/musikfrosch/lib/python3.11/site-packages/urllib3/connectionpool.py", line 714, in urlopen
    httplib_response = self._make_request(
                       ^^^^^^^^^^^^^^^^^^^
  File "/home/a163/anaconda3/envs/musikfrosch/lib/python3.11/site-packages/urllib3/connectionpool.py", line 403, in _make_request
    self._validate_conn(conn)
  File "/home/a163/anaconda3/envs/musikfrosch/lib/python3.11/site-packages/urllib3/connectionpool.py", line 1053, in _validate_conn
    conn.connect()
  File "/home/a163/anaconda3/envs/musikfrosch/lib/python3.11/site-packages/urllib3/connection.py", line 363, in connect
    self.sock = conn = self._new_conn()
                       ^^^^^^^^^^^^^^^^
  File "/home/a163/anaconda3/envs/musikfrosch/lib/python3.11/site-packages/urllib3/connection.py", line 186, in _new_conn
    raise NewConnectionError(
urllib3.exceptions.NewConnectionError: <urllib3.connection.HTTPSConnection object at 0x7255f4528b50>: Failed to establish a new connection: [Errno -3] Temporary failure in name resolution

During handling of the above exception, another exception occurred:

Traceback (most recent call last):
  File "/home/a163/anaconda3/envs/musikfrosch/lib/python3.11/site-packages/requests/adapters.py", line 486, in send
    resp = conn.urlopen(
           ^^^^^^^^^^^^^
  File "/home/a163/anaconda3/envs/musikfrosch/lib/python3.11/site-packages/urllib3/connectionpool.py", line 798, in urlopen
    retries = retries.increment(
              ^^^^^^^^^^^^^^^^^^
  File "/home/a163/anaconda3/envs/musikfrosch/lib/python3.11/site-packages/urllib3/util/retry.py", line 592, in increment
    raise MaxRetryError(_pool, url, error or ResponseError(cause))
urllib3.exceptions.MaxRetryError: HTTPSConnectionPool(host='accounts.spotify.com', port=443): Max retries exceeded with url: /api/token (Caused by NewConnectionError('<urllib3.connection.HTTPSConnection object at 0x7255f4528b50>: Failed to establish a new connection: [Errno -3] Temporary failure in name resolution'))

During handling of the above exception, another exception occurred:

Traceback (most recent call last):
  File "/home/a163/GitRepo/musikfrosch_mc/_main_.py", line 25, in <module>
    import scrapers as s
  File "/home/a163/GitRepo/musikfrosch_mc/scrapers.py", line 17, in <module>
    import class_dictionary as cd
  File "/home/a163/GitRepo/musikfrosch_mc/class_dictionary.py", line 23, in <module>
    SP_a163 = spot.spotfy_class(a163_LOGIN, SCOPE)
              ^^^^^^^^^^^^^^^^^^^^^^^^^^^^^^^^^^^^
  File "/home/a163/GitRepo/musikfrosch_mc/spotypys.py", line 54, in __init__
    token = util.prompt_for_user_token(username=SP_LOGIN[0],
            ^^^^^^^^^^^^^^^^^^^^^^^^^^^^^^^^^^^^^^^^^^^^^^^^
  File "/home/a163/anaconda3/envs/musikfrosch/lib/python3.11/site-packages/spotipy/util.py", line 96, in prompt_for_user_token
    token_info = sp_oauth.validate_token(sp_oauth.cache_handler.get_cached_token())
                 ^^^^^^^^^^^^^^^^^^^^^^^^^^^^^^^^^^^^^^^^^^^^^^^^^^^^^^^^^^^^^^^^^^
  File "/home/a163/anaconda3/envs/musikfrosch/lib/python3.11/site-packages/spotipy/oauth2.py", line 380, in validate_token
    token_info = self.refresh_access_token(
                 ^^^^^^^^^^^^^^^^^^^^^^^^^^
  File "/home/a163/anaconda3/envs/musikfrosch/lib/python3.11/site-packages/spotipy/oauth2.py", line 581, in refresh_access_token
    response = self._session.post(
               ^^^^^^^^^^^^^^^^^^^
  File "/home/a163/anaconda3/envs/musikfrosch/lib/python3.11/site-packages/requests/sessions.py", line 637, in post
    return self.request("POST", url, data=data, json=json, **kwargs)
           ^^^^^^^^^^^^^^^^^^^^^^^^^^^^^^^^^^^^^^^^^^^^^^^^^^^^^^^^^
  File "/home/a163/anaconda3/envs/musikfrosch/lib/python3.11/site-packages/requests/sessions.py", line 589, in request
    resp = self.send(prep, **send_kwargs)
           ^^^^^^^^^^^^^^^^^^^^^^^^^^^^^^
  File "/home/a163/anaconda3/envs/musikfrosch/lib/python3.11/site-packages/requests/sessions.py", line 703, in send
    r = adapter.send(request, **kwargs)
        ^^^^^^^^^^^^^^^^^^^^^^^^^^^^^^^
  File "/home/a163/anaconda3/envs/musikfrosch/lib/python3.11/site-packages/requests/adapters.py", line 519, in send
    raise ConnectionError(e, request=request)
requests.exceptions.ConnectionError: HTTPSConnectionPool(host='accounts.spotify.com', port=443): Max retries exceeded with url: /api/token (Caused by NewConnectionError('<urllib3.connection.HTTPSConnection object at 0x7255f4528b50>: Failed to establish a new connection: [Errno -3] Temporary failure in name resolution'))
