  ███╗   ███╗██╗   ██╗███████╗██╗ ██████╗███████╗██████╗  ██████╗ ███████╗ ██████╗██╗  ██╗███╗   ███╗ ██████╗
  ████╗ ████║██║   ██║██╔════╝██║██╔════╝██╔════╝██╔══██╗██╔═══██╗██╔════╝██╔════╝██║  ██║████╗ ████║██╔════╝
  ██╔████╔██║██║   ██║███████╗██║██║     █████╗  ██████╔╝██║   ██║███████╗██║     ███████║██╔████╔██║██║     
  ██║╚██╔╝██║██║   ██║╚════██║██║██║     ██╔══╝  ██╔══██╗██║   ██║╚════██║██║     ██╔══██║██║╚██╔╝██║██║     
  ██║ ╚═╝ ██║╚██████╔╝███████║██║╚██████╗██║     ██║  ██║╚██████╔╝███████║╚██████╗██║  ██║██║ ╚═╝ ██║╚██████╗
  ╚═╝     ╚═╝ ╚═════╝ ╚══════╝╚═╝ ╚═════╝╚═╝     ╚═╝  ╚═╝ ╚═════╝ ╚══════╝ ╚═════╝╚═╝  ╚═╝╚═╝     ╚═╝ ╚═════╝
Current date and time: Di 18. Feb 12:03:29 CET 2025
Current folder: /

Traceback (most recent call last):
  File "/home/a163/anaconda3/envs/musikfrosch/lib/python3.11/site-packages/urllib3/connectionpool.py", line 714, in urlopen
    httplib_response = self._make_request(
                       ^^^^^^^^^^^^^^^^^^^
  File "/home/a163/anaconda3/envs/musikfrosch/lib/python3.11/site-packages/urllib3/connectionpool.py", line 466, in _make_request
    six.raise_from(e, None)
  File "<string>", line 3, in raise_from
  File "/home/a163/anaconda3/envs/musikfrosch/lib/python3.11/site-packages/urllib3/connectionpool.py", line 461, in _make_request
    httplib_response = conn.getresponse()
                       ^^^^^^^^^^^^^^^^^^
  File "/home/a163/anaconda3/envs/musikfrosch/lib/python3.11/http/client.py", line 1378, in getresponse
    response.begin()
  File "/home/a163/anaconda3/envs/musikfrosch/lib/python3.11/http/client.py", line 318, in begin
    version, status, reason = self._read_status()
                              ^^^^^^^^^^^^^^^^^^^
  File "/home/a163/anaconda3/envs/musikfrosch/lib/python3.11/http/client.py", line 287, in _read_status
    raise RemoteDisconnected("Remote end closed connection without"
http.client.RemoteDisconnected: Remote end closed connection without response

During handling of the above exception, another exception occurred:

Traceback (most recent call last):
  File "/home/a163/anaconda3/envs/musikfrosch/lib/python3.11/site-packages/requests/adapters.py", line 486, in send
    resp = conn.urlopen(
           ^^^^^^^^^^^^^
  File "/home/a163/anaconda3/envs/musikfrosch/lib/python3.11/site-packages/urllib3/connectionpool.py", line 798, in urlopen
    retries = retries.increment(
              ^^^^^^^^^^^^^^^^^^
  File "/home/a163/anaconda3/envs/musikfrosch/lib/python3.11/site-packages/urllib3/util/retry.py", line 550, in increment
    raise six.reraise(type(error), error, _stacktrace)
          ^^^^^^^^^^^^^^^^^^^^^^^^^^^^^^^^^^^^^^^^^^^^
  File "/home/a163/anaconda3/envs/musikfrosch/lib/python3.11/site-packages/urllib3/packages/six.py", line 769, in reraise
    raise value.with_traceback(tb)
  File "/home/a163/anaconda3/envs/musikfrosch/lib/python3.11/site-packages/urllib3/connectionpool.py", line 714, in urlopen
    httplib_response = self._make_request(
                       ^^^^^^^^^^^^^^^^^^^
  File "/home/a163/anaconda3/envs/musikfrosch/lib/python3.11/site-packages/urllib3/connectionpool.py", line 466, in _make_request
    six.raise_from(e, None)
  File "<string>", line 3, in raise_from
  File "/home/a163/anaconda3/envs/musikfrosch/lib/python3.11/site-packages/urllib3/connectionpool.py", line 461, in _make_request
    httplib_response = conn.getresponse()
                       ^^^^^^^^^^^^^^^^^^
  File "/home/a163/anaconda3/envs/musikfrosch/lib/python3.11/http/client.py", line 1378, in getresponse
    response.begin()
  File "/home/a163/anaconda3/envs/musikfrosch/lib/python3.11/http/client.py", line 318, in begin
    version, status, reason = self._read_status()
                              ^^^^^^^^^^^^^^^^^^^
  File "/home/a163/anaconda3/envs/musikfrosch/lib/python3.11/http/client.py", line 287, in _read_status
    raise RemoteDisconnected("Remote end closed connection without"
urllib3.exceptions.ProtocolError: ('Connection aborted.', RemoteDisconnected('Remote end closed connection without response'))

During handling of the above exception, another exception occurred:

Traceback (most recent call last):
  File "/home/a163/GitRepo/musikfrosch_mc/_main_.py", line 25, in <module>
    import scrapers as s
  File "/home/a163/GitRepo/musikfrosch_mc/scrapers.py", line 17, in <module>
    import class_dictionary as cd
  File "/home/a163/GitRepo/musikfrosch_mc/class_dictionary.py", line 23, in <module>
    SP_a163 = spot.spotfy_class(a163_LOGIN, SCOPE)
              ^^^^^^^^^^^^^^^^^^^^^^^^^^^^^^^^^^^^
  File "/home/a163/GitRepo/musikfrosch_mc/spotypys.py", line 54, in __init__
    token = util.prompt_for_user_token(username=SP_LOGIN[0],
            ^^^^^^^^^^^^^^^^^^^^^^^^^^^^^^^^^^^^^^^^^^^^^^^^
  File "/home/a163/anaconda3/envs/musikfrosch/lib/python3.11/site-packages/spotipy/util.py", line 96, in prompt_for_user_token
    token_info = sp_oauth.validate_token(sp_oauth.cache_handler.get_cached_token())
                 ^^^^^^^^^^^^^^^^^^^^^^^^^^^^^^^^^^^^^^^^^^^^^^^^^^^^^^^^^^^^^^^^^^
  File "/home/a163/anaconda3/envs/musikfrosch/lib/python3.11/site-packages/spotipy/oauth2.py", line 380, in validate_token
    token_info = self.refresh_access_token(
                 ^^^^^^^^^^^^^^^^^^^^^^^^^^
  File "/home/a163/anaconda3/envs/musikfrosch/lib/python3.11/site-packages/spotipy/oauth2.py", line 581, in refresh_access_token
    response = self._session.post(
               ^^^^^^^^^^^^^^^^^^^
  File "/home/a163/anaconda3/envs/musikfrosch/lib/python3.11/site-packages/requests/sessions.py", line 637, in post
    return self.request("POST", url, data=data, json=json, **kwargs)
           ^^^^^^^^^^^^^^^^^^^^^^^^^^^^^^^^^^^^^^^^^^^^^^^^^^^^^^^^^
  File "/home/a163/anaconda3/envs/musikfrosch/lib/python3.11/site-packages/requests/sessions.py", line 589, in request
    resp = self.send(prep, **send_kwargs)
           ^^^^^^^^^^^^^^^^^^^^^^^^^^^^^^
  File "/home/a163/anaconda3/envs/musikfrosch/lib/python3.11/site-packages/requests/sessions.py", line 703, in send
    r = adapter.send(request, **kwargs)
        ^^^^^^^^^^^^^^^^^^^^^^^^^^^^^^^
  File "/home/a163/anaconda3/envs/musikfrosch/lib/python3.11/site-packages/requests/adapters.py", line 501, in send
    raise ConnectionError(err, request=request)
requests.exceptions.ConnectionError: ('Connection aborted.', RemoteDisconnected('Remote end closed connection without response'))
